    operations.impl.create_table(table)
           ^^^^^
  File "<frozen importlib._bootstrap_external>", line 940, in exec_module
  File "/opt/venv/lib/python3.11/site-packages/alembic/ddl/impl.py", line 366, in create_table
  File "/opt/venv/lib/python3.11/site-packages/sqlalchemy/sql/ddl.py", line 181, in _execute_on_connection
  File "/opt/venv/lib/python3.11/site-packages/alembic/runtime/migration.py", line 627, in run_migrations
  File "<frozen importlib._bootstrap>", line 241, in _call_with_frames_removed
    self._exec(schema.CreateTable(table))
    ret = self._execute_context(
  File "/app/migrations/versions/304d3e98ef6d_initial_complete_schema.py", line 21, in upgrade
    step.migration_fn(**kw)
    return connection._execute_ddl(
  File "/opt/venv/lib/python3.11/site-packages/alembic/ddl/impl.py", line 207, in _exec
           ^^^^^^^^^^^^^^^^^^^^^^^^
    return conn.execute(construct, multiparams)
  File "/opt/venv/lib/python3.11/site-packages/sqlalchemy/engine/base.py", line 1528, in _execute_ddl
          ^^^^^^^^^^^^^^^^^^^^^^
           ^^^^^^^^^^^^^^^^^^^^^^^^^^^^^^^^^^^^
  File "/opt/venv/lib/python3.11/site-packages/sqlalchemy/engine/base.py", line 1848, in _execute_context
  File "/opt/venv/lib/python3.11/site-packages/sqlalchemy/engine/base.py", line 1416, in execute
    return self._exec_single_context(
    op.create_table('user',
  File "<string>", line 8, in create_table
  File "<string>", line 3, in create_table
  File "/opt/venv/lib/python3.11/site-packages/alembic/operations/ops.py", line 1311, in create_table
    return operations.invoke(op)
           ^^^^^^^^^^^^^^^^^^^^^
  File "/opt/venv/lib/python3.11/site-packages/alembic/operations/base.py", line 445, in invoke
    return fn(self, operation)
           ^^^^^^^^^^^^^^^^^^^
  File "/opt/venv/lib/python3.11/site-packages/alembic/operations/toimpl.py", line 131, in create_table
           ^^^^^^^^^^^^^^^^^^^^^^^^^^
  File "/opt/venv/lib/python3.11/site-packages/sqlalchemy/engine/base.py", line 1988, in _exec_single_context
    self._handle_dbapi_exception(
  File "/opt/venv/lib/python3.11/site-packages/sqlalchemy/engine/base.py", line 2344, in _handle_dbapi_exception
    raise sqlalchemy_exception.with_traceback(exc_info[2]) from e
  File "/opt/venv/lib/python3.11/site-packages/sqlalchemy/engine/base.py", line 1969, in _exec_single_context
    self.dialect.do_execute(
  File "/opt/venv/lib/python3.11/site-packages/sqlalchemy/engine/default.py", line 922, in do_execute
    cursor.execute(statement, parameters)
sqlalchemy.exc.ProgrammingError: (psycopg2.errors.DuplicateTable) relation "user" already exists
[SQL: 
CREATE TABLE "user" (
	id SERIAL NOT NULL, 
	username VARCHAR(80) NOT NULL, 
	email VARCHAR(120) NOT NULL, 
	password_hash VARCHAR(255) NOT NULL, 
	created_at TIMESTAMP WITHOUT TIME ZONE, 
	is_active BOOLEAN, 
	is_admin BOOLEAN NOT NULL, 
	is_superuser BOOLEAN NOT NULL, 
	PRIMARY KEY (id), 
	UNIQUE (email), 
	UNIQUE (username)
)
]
(Background on this error at: https://sqlalche.me/e/20/f405)
[2025-10-01 12:59:24,217] INFO in config: PhotoVault startup
2025-10-01 12:59:24,217 INFO: PhotoVault startup [in /app/photovault/config.py:201]
[2025-10-01 12:59:24,428] INFO in app_storage_service: Not in Replit environment, skipping App Storage initialization
2025-10-01 12:59:24,428 INFO: Not in Replit environment, skipping App Storage initialization [in /app/photovault/services/app_storage_service.py:22]
[2025-10-01 12:59:24,704] INFO in image_enhancement: OpenCV available - full image enhancement features enabled
2025-10-01 12:59:24,704 INFO: OpenCV available - full image enhancement features enabled [in /app/photovault/utils/image_enhancement.py:19]
[2025-10-01 12:59:24,721] INFO in face_detection: Haar cascade face detector loaded
2025-10-01 12:59:24,721 INFO: Haar cascade face detector loaded [in /app/photovault/utils/face_detection.py:42]
2025-10-01 12:59:24,721 INFO: DNN model file not found - using Haar cascade only [in /app/photovault/utils/face_detection.py:64]
[2025-10-01 12:59:24,721] INFO in face_detection: DNN model file not found - using Haar cascade only
[2025-10-01 12:59:24,721] INFO in face_detection: Face detection initialized successfully
2025-10-01 12:59:24,721 INFO: Face detection initialized successfully [in /app/photovault/utils/face_detection.py:27]
[2025-10-01 12:59:24,724] INFO in face_recognition: OpenCV face recognizer initialized
2025-10-01 12:59:24,724 INFO: OpenCV face recognizer initialized [in /app/photovault/utils/face_recognition.py:46]
[2025-10-01 12:59:24,738] INFO in face_recognition: Face recognition models loaded
2025-10-01 12:59:24,738 INFO: Face recognition models loaded [in /app/photovault/utils/face_recognition.py:58]
[2025-10-01 12:59:24,738] INFO in face_recognition: No cached encodings found - starting fresh
2025-10-01 12:59:24,738 INFO: No cached encodings found - starting fresh [in /app/photovault/utils/face_recognition.py:76]
[2025-10-01 12:59:24,738] INFO in face_recognition: Face recognition initialized successfully
2025-10-01 12:59:24,738 INFO: Face recognition initialized successfully [in /app/photovault/utils/face_recognition.py:31]
2025-10-01 12:59:24,743 INFO: OpenCV available for photo detection [in /app/photovault/utils/photo_detection.py:18]
[2025-10-01 12:59:24,743] INFO in photo_detection: OpenCV available for photo detection
[2025-10-01 12:59:25,560] INFO in __init__: Database connection verified (production mode)
2025-10-01 12:59:25,560 INFO: Database connection verified (production mode) [in /app/photovault/__init__.py:339]
INFO:photovault:Database connection verified (production mode)
[2025-10-01 12:59:25,668] INFO in __init__: Subscription plans: created 0, updated 5
2025-10-01 12:59:25,668 INFO: Subscription plans: created 0, updated 5 [in /app/photovault/__init__.py:140]
INFO:photovault:Subscription plans: created 0, updated 5
PhotoVault WSGI: Environment = production
PhotoVault WSGI: Debug = False
PhotoVault WSGI: Config = Config
PhotoVault WSGI: Database URI set = Yes
PhotoVault WSGI: App created successfully, ready to handle requests
INFO  [alembic.runtime.migration] Context impl PostgresqlImpl.
INFO  [alembic.runtime.migration] Will assume transactional DDL.
INFO  [alembic.runtime.migration] Running upgrade  -> 304d3e98ef6d, Initial complete schema
Traceback (most recent call last):
  File "/opt/venv/lib/python3.11/site-packages/sqlalchemy/engine/base.py", line 1969, in _exec_single_context
    self.dialect.do_execute(
  File "/opt/venv/lib/python3.11/site-packages/sqlalchemy/engine/default.py", line 922, in do_execute
    cursor.execute(statement, parameters)
psycopg2.errors.DuplicateTable: relation "user" already exists
The above exception was the direct cause of the following exception:
Traceback (most recent call last):
  File "<frozen runpy>", line 198, in _run_module_as_main
  File "<frozen runpy>", line 88, in _run_code
  File "/opt/venv/lib/python3.11/site-packages/flask/__main__.py", line 3, in <module>
    main()
  File "/opt/venv/lib/python3.11/site-packages/flask/cli.py", line 1105, in main
    cli.main()
  File "/opt/venv/lib/python3.11/site-packages/click/core.py", line 1078, in main
    rv = self.invoke(ctx)
         ^^^^^^^^^^^^^^^^
  File "/opt/venv/lib/python3.11/site-packages/click/core.py", line 1688, in invoke
    return _process_result(sub_ctx.command.invoke(sub_ctx))
                           ^^^^^^^^
^^^^^^^^^^^^^^^^^^^^^^^
  File "/opt/venv/lib/python3.11/site-packages/click/core.py", line 1688, in invoke
    return _process_result(sub_ctx.command.invoke(sub_ctx))
                           ^^^^^^^^^^^^^^^^^^^^^^^^^
^^^^^^
  File "/opt/venv/lib/python3.11/site-packages/click/core.py", line 1434, in invoke
    return ctx.invoke(self.callback, **ctx.params)
           ^^^^^^^^^^^^^^^^^^^^^^^^^^^^^^^^^^^^^^^
  File "/opt/venv/lib/python3.11/site-packages/click/core.py", line 783, in invoke
    return __callback(*args, **kwargs)
           ^^^^^^^^^^^^^^^^^^^^^^^^^^^
  File "/opt/venv/lib/python3.11/site-packages/click/decorators.py", line 33, in new_func
    return f(get_current_context(), *args, **kwargs)
           ^^^^^^^^^^^^^^^^^^^^^^^^^^^^^^^^^^^^^^^^^
  File "/opt/venv/lib/python3.11/site-packages/flask/cli.py", line 386, in decorator
    return ctx.invoke(f, *args, **kwargs)
           ^^^^^^^^^^^^^^^^^^^^^^^^^^^^^^
    self.dialect.do_execute(
  File "/opt/venv/lib/python3.11/site-packages/click/core.py", line 783, in invoke
  File "/opt/venv/lib/python3.11/site-packages/sqlalchemy/engine/default.py", line 922, in do_execute
    return __callback(*args, **kwargs)
           ^^^^^^^^^^^^^^^^^^^^^^^^^^^
    cursor.execute(statement, parameters)
sqlalchemy.exc.ProgrammingError: (psycopg2.errors.DuplicateTable) relation "user" already exists
  File "/opt/venv/lib/python3.11/site-packages/flask_migrate/cli.py", line 157, in upgrade
    _upgrade(directory or g.directory, revision, sql, tag, x_arg or g.x_arg)
[SQL: 
  File "/opt/venv/lib/python3.11/site-packages/flask_migrate/__init__.py", line 111, in wrapped
CREATE TABLE "user" (
    f(*args, **kwargs)
	id SERIAL NOT NULL, 
  File "/opt/venv/lib/python3.11/site-packages/flask_migrate/__init__.py", line 200, in upgrade
	username VARCHAR(80) NOT NULL, 
	email VARCHAR(120) NOT NULL, 
    command.upgrade(config, revision, sql=sql, tag=tag)
	password_hash VARCHAR(255) NOT NULL, 
  File "/opt/venv/lib/python3.11/site-packages/alembic/command.py", line 403, in upgrade
	created_at TIMESTAMP WITHOUT TIME ZONE, 
    script.run_env()
	is_active BOOLEAN, 
  File "/opt/venv/lib/python3.11/site-packages/alembic/script/base.py", line 583, in run_env
	is_admin BOOLEAN NOT NULL, 
    util.load_python_file(self.dir, "env.py")
	is_superuser BOOLEAN NOT NULL, 
	PRIMARY KEY (id), 
  File "/opt/venv/lib/python3.11/site-packages/alembic/util/pyfiles.py", line 95, in load_python_file
	UNIQUE (email), 
    module = load_module_py(module_id, path)
	UNIQUE (username)
             ^^^^^^^^^^^^^^^^^^^^^^^^^^^^^^^
)
  File "/opt/venv/lib/python3.11/site-packages/alembic/util/pyfiles.py", line 113, in load_module_py
    spec.loader.exec_module(module)  # type: ignore
]
    ^^^^^^^^^^^^^^^^^^^^^^^^^^^^^^^
(Background on this error at: https://sqlalche.me/e/20/f405)
  File "<frozen importlib._bootstrap_external>", line 940, in exec_module
  File "<frozen importlib._bootstrap>", line 241, in _call_with_frames_removed
  File "/app/migrations/env.py", line 113, in <module>
    run_migrations_online()
  File "/app/migrations/env.py", line 107, in run_migrations_online
    context.run_migrations()
  File "<string>", line 8, in run_migrations
  File "/opt/venv/lib/python3.11/site-packages/alembic/runtime/environment.py", line 948, in run_migrations
